Workbook

Sheet Sales Performance Analysis
A1: Summary Average of Order
A2: Year | B2: Revenue | C2: Total Transaction | D2: AOV(Average Order)
A3: 2020 | B3: =GETPIVOTDATA("TotalOrderTransaction",$A$10,"Years (OrderDate)",2020) -> 111070848160 | C3: =COUNTIFS('Sales Order'!D$1:D$1029,">=01/01/2020",'Sales Order'!D$1:D$1029,"<=31/12/2020") -> 355 | D3: =B3/C3 -> 3.1287563e+08
A4: 2021 | B4: =GETPIVOTDATA("TotalOrderTransaction",$A$10,"Years (OrderDate)",2021) -> 91960394232 | C4: =COUNTIFS('Sales Order'!D$1:D$1029,">=01/01/2021",'Sales Order'!D$1:D$1029,"<=31/12/2021") -> 326 | D4: =B4/C4 -> 2.820871e+08
A5: 2022 | B5: =GETPIVOTDATA("TotalOrderTransaction",$A$10,"Years (OrderDate)",2022) -> 93738658411 | C5: =COUNTIFS('Sales Order'!D$1:D$1029,">=01/01/2022",'Sales Order'!D$1:D$1029,"<=31/12/2022") -> 347 | D5: =B5/C5 -> 2.7014023e+08
A6: Total 2020 - 2022 | B6: =SUM(B3:B5) -> 296769900803 | C6: =SUM(C3:C5) -> 1028 | D6: =B6/C6 -> 2.8868667e+08
A9: Sales Trend
A10: Row Labels | B10: Sum of TotalOrderTransaction
A11: 2020 | B11: 111070848160
A12: Jan | B12: 8413435101
A13: Feb | B13: 8873118039
A14: Mar | B14: 9403906569
A15: Apr | B15: 13014811284
A16: May | B16: 7369746605
A17: Jun | B17: 9495793700
A18: Jul | B18: 6938459794
A19: Aug | B19: 9982499020
A20: Sep | B20: 5559243162
A21: Oct | B21: 6688805798
A22: Nov | B22: 13241776433
... A50: Grand Total | B50: 296769900803
A51: Seasonality
A52: Sum of TotalOrderTransaction | B52: Column Labels
A53: Row Labels | B53: 2020 | C53: 2021 | D53: 2022 | E53: Grand Total
A54: Jan | B54: 8413435101 | C54: 6006920922 | D54: 8994015941 | E54: 23414371964
A55: Feb | B55: 8873118039 | C55: 10810944665 | D55: 6143660865 | E55: 25827723569
A56: Mar | B56: 9403906569 | C56: 10531075262 | D56: 7050162013 | E56: 26985143844
A57: Apr | B57: 13014811284 | C57: 5909070377 | D57: 10076428067 | E57: 29000309728
A58: May | B58: 7369746605 | C58: 10961188957 | D58: 8990850316 | E58: 27321785878
A59: Jun | B59: 9495793700 | C59: 7378988884 | D59: 6694582334 | E59: 23569364918
A60: Jul | B60: 6938459794 | C60: 6490006504 | D60: 4903260764 | E60: 18331727062
A61: Aug | B61: 9982499020 | C61: 7748171035 | D61: 6487507383 | E61: 24218177438
A62: Sep | B62: 5559243162 | C62: 3724306588 | D62: 8517428394 | E62: 17800978144
A63: Oct | B63: 6688805798 | C63: 7350906379 | D63: 13173162638 | E63: 27212874815
A64: Nov | B64: 13241776433 | C64: 7823993577 | D64: 7891588474 | E64: 28957358484
A65: Dec | B65: 12089252655 | C65: 7224821082 | D65: 4816011222 | E65: 24130084959
A66: Grand Total | B66: 111070848160 | C66: 91960394232 | D66: 93738658411 | E66: 296769900803
A88: Growth Analysis(comparing sales MoM & YoY)
A89: MoM | B89: 1st month to compare data | C89: 2nd month to compare data | D89: Growth Percentage
A90: Jan 2020 - Feb 2020 | B90: 8413435101 | C90: 8873118039 | D90: =(C90-B90)/B90 -> 0.054636772
...

Sheet Sales Order
A1: SalesOrderID | B1: PatnerStoreID | C1: SalesTeamID | D1: OrderDate | E1: Region Sales | F1: Payment | G1: TotalOrderTransaction | H1: Note | I1: Region Sales Team | J1: Sales Teams Method | K1: Patner Store | L1: Patner Type | M1: Region_Sales | N1: Province_Sales
A2: SO0001 | B2: PS0040 | C2: ST0003 | D2: 43832 | E2: Sumatera & Kalimantan | F2: CASH | G2: 114641676 | I2: =VLOOKUP(C2,'Sales Team'!A$1:C$6,2,0) -> Sales Sumatera -Kalimantan Region Team | J2: =VLOOKUP(C2,'Sales Team'!A$1:D$6,4,0) -> OnlineMarketing/Corporate Negotiate/Patnership Contract | K2: =VLOOKUP(B2,'Patner Store'!A$1:F$51,2,0) -> Olahraga Gemilang | L2: =VLOOKUP(B2,'Patner Store'!A$1:F$51,3,0) -> Retail | M2: =VLOOKUP(B2,'Patner Store'!A$1:F$51,4,0) -> Kalimantan | N2: =VLOOKUP(B2,'Patner Store'!A$1:F$51,5,0) -> Central Kalimantan
A3: SO0002 | B3: PS0046 | C3: ST0003 | D3: 43832 | E3: Sumatera & Kalimantan | F3: CASH | G3: 44870970 | I3: =VLOOKUP(C3,'Sales Team'!A$1:C$6,2,0) -> Sales Sumatera -Kalimantan Region Team | J3: =VLOOKUP(C3,'Sales Team'!A$1:D$6,4,0) -> OnlineMarketing/Corporate Negotiate/Patnership Contract | K3: =VLOOKUP(B3,'Patner Store'!A$1:F$51,2,0) -> Markas Olahraga | L3: =VLOOKUP(B3,'Patner Store'!A$1:F$51,3,0) -> Retail | M3: =VLOOKUP(B3,'Patner Store'!A$1:F$51,4,0) -> Kalimantan | N3: =VLOOKUP(B3,'Patner Store'!A$1:F$51,5,0) -> South Kalimantan
A4: SO0003 | B4: PS0024 | C4: ST0001 | D4: 43833 | E4: Jakarta | F4: CREDIT | G4: 1101806050 | H4: transaction as agreed with the vendor | I4: =VLOOKUP(C4,'Sales Team'!A$1:C$6,2,0) -> Online Sales Team | J4: =VLOOKUP(C4,'Sales Team'!A$1:D$6,4,0) -> OnlineMarketing | K4: =VLOOKUP(B4,'Patner Store'!A$1:F$51,2,0) -> SportChampion10 | L4: =VLOOKUP(B4,'Patner Store'!A$1:F$51,3,0) -> Retail | M4: =VLOOKUP(B4,'Patner Store'!A$1:F$51,4,0) -> Java | N4: =VLOOKUP(B4,'Patner Store'!A$1:F$51,5,0) -> Jakarta
A5: SO0004 | B5: PS0048 | C5: ST0003 | D5: 43834 | E5: Sumatera & Kalimantan | F5: CASH | G5: 10698048 | I5: =VLOOKUP(C5,'Sales Team'!A$1:C$6,2,0) -> Sales Sumatera -Kalimantan Region Team | J5: =VLOOKUP(C5,'Sales Team'!A$1:D$6,4,0) -> OnlineMarketing/Corporate Negotiate/Patnership Contract | K5: =VLOOKUP(B5,'Patner Store'!A$1:F$51,2,0) -> Toko Olahraga Mandiri | L5: =VLOOKUP(B5,'Patner Store'!A$1:F$51,3,0) -> Retail | M5: =VLOOKUP(B5,'Patner Store'!A$1:F$51,4,0) -> Kalimantan | N5: =VLOOKUP(B5,'Patner Store'!A$1:F$51,5,0) -> South Kalimantan
A6: SO0005 | B6: PS0024 | C6: ST0001 | D6: 43835 | E6: Jakarta | F6: CREDIT | G6: 250560000 | I6: =VLOOKUP(C6,'Sales Team'!A$1:C$6,2,0) -> Online Sales Team | J6: =VLOOKUP(C6,'Sales Team'!A$1:D$6,4,0) -> OnlineMarketing | K6: =VLOOKUP(B6,'Patner Store'!A$1:F$51,2,0) -> SportChampion10 | L6: =VLOOKUP(B6,'Patner Store'!A$1:F$51,3,0) -> Retail | M6: =VLOOKUP(B6,'Patner Store'!A$1:F$51,4,0) -> Java | N6: =VLOOKUP(B6,'Patner Store'!A$1:F$51,5,0) -> Jakarta
A7: SO0006 | B7: PS0012 | C7: ST0003 | D7: 43837 | E7: Sumatera & Kalimantan | F7: CASH | G7: 11269440 | I7: =VLOOKUP(C7,'Sales Team'!A$1:C$6,2,0) -> Sales Sumatera -Kalimantan Region Team | J7: =VLOOKUP(C7,'Sales Team'!A$1:D$6,4,0) -> OnlineMarketing/Corporate Negotiate/Patnership Contract | K7: =VLOOKUP(B7,'Patner Store'!A$1:F$51,2,0) -> Adi Shop | L7: =VLOOKUP(B7,'Patner Store'!A$1:F$51,3,0) -> Retail | M7: =VLOOKUP(B7,'Patner Store'!A$1:F$51,4,0) -> Kalimantan | N7: =VLOOKUP(B7,'Patner Store'!A$1:F$51,5,0) -> South Kalimantan
A8: SO0007 | B8: PS0024 | C8: ST0001 | D8: 43839 | E8: Jakarta | F8: CREDIT | G8: 427027780 | I8: =VLOOKUP(C8,'Sales Team'!A$1:C$6,2,0) -> Online Sales Team | J8: =VLOOKUP(C8,'Sales Team'!A$1:D$6,4,0) -> OnlineMarketing | K8: =VLOOKUP(B8,'Patner Store'!A$1:F$51,2,0) -> SportChampion10 | L8: =VLOOKUP(B8,'Patner Store'!A$1:F$51,3,0) -> Retail | M8: =VLOOKUP(B8,'Patner Store'!A$1:F$51,4,0) -> Java | N8: =VLOOKUP(B8,'Patner Store'!A$1:F$51,5,0) -> Jakarta
A9: SO0008 | B9: PS0045 | C9: ST0005 | D9: 43840 | E9: Bali, East & West Nusa Tenggara | F9: CREDIT | G9: 614116940 | I9: =VLOOKUP(C9,'Sales Team'!A$1:C$6,2,0) -> Sales Region Bali - Nusa Tenggara Team | J9: =VLOOKUP(C9,'Sales Team'!A$1:D$6,4,0) -> Corporate Negotiate/Patnership Contract | K9: =VLOOKUP(B9,'Patner Store'!A$1:F$51,2,0) -> Toko Olahraga NTB | L9: =VLOOKUP(B9,'Patner Store'!A$1:F$51,3,0) -> Retail | M9: =VLOOKUP(B9,'Patner Store'!A$1:F$51,4,0) -> Nusa Tenggara | N9: =VLOOKUP(B9,'Patner Store'!A$1:F$51,5,0) -> West Nusa Tenggara
A10: SO0009 | B10: PS0037 | C10: ST0002 | D10: 43841 | E10: Java | F10: CASH | G10: 175419850 | I10: =VLOOKUP(C10,'Sales Team'!A$1:C$6,2,0) -> Sales Java Region Team | J10: =VLOOKUP(C10,'Sales Team'!A$1:D$6,4,0) -> OnlineMarketing/Corporate Negotiate/Patnership Contract | K10: =VLOOKUP(B10,'Patner Store'!A$1:F$51,2,0) -> Toko Joko Sport | L10: =VLOOKUP(B10,'Patner Store'!A$1:F$51,3,0) -> Retail | M10: =VLOOKUP(B10,'Patner Store'!A$1:F$51,4,0) -> Java | N10: =VLOOKUP(B10,'Patner Store'!A$1:F$51,5,0) -> East Java
A11: SO0010 | B11: PS0037 | C11: ST0002 | D11: 43841 | E11: Java | F11: CREDIT | G11: 669084987 | I11: =VLOOKUP(C11,'Sales Team'!A$1:C$6,2,0) -> Sales Java Region Team | J11: =VLOOKUP(C11,'Sales Team'!A$1:D$6,4,0) -> OnlineMarketing/Corporate Negotiate/Patnership Contract | K11: =VLOOKUP(B11,'Patner Store'!A$1:F$51,2,0) -> Toko Joko Sport | L11: =VLOOKUP(B11,'Patner Store'!A$1:F$51,3,0) -> Retail | M11: =VLOOKUP(B11,'Patner Store'!A$1:F$51,4,0) -> Java | N11: =VLOOKUP(B11,'Patner Store'!A$1:F$51,5,0) -> East Java
A12: SO0011 | B12: PS0003 | C12: ST0003 | D12: 43843 | E12: Sumatera & Kalimantan | F12: CASH | G12: 70191310 | H12: The transaction agreement has undergone changes | I12: =VLOOKUP(C12,'Sales Team'!A$1:C$6,2,0) -> Sales Sumatera -Kalimantan Region Team | J12: =VLOOKUP(C12,'Sales Team'!A$1:D$6,4,0) -> OnlineMarketing/Corporate Negotiate/Patnership Contract | K12: =VLOOKUP(B12,'Patner Store'!A$1:F$51,2,0) -> Toko Gelora Sport | L12: =VLOOKUP(B12,'Patner Store'!A$1:F$51,3,0) -> Retail | M12: =VLOOKUP(B12,'Patner Store'!A$1:F$51,4,0) -> Kalimantan | N12: =VLOOKUP(B12,'Patner Store'!A$1:F$51,5,0) -> Central Kalimantan
A13: SO0012 | B13: PS0043 | C13: ST0004 | D13: 43847 | E13: Sulawesi, Maluku, North Maluku | F13: CASH | G13: 97549900 | I13: =VLOOKUP(C13,'Sales Team'!A$1:C$6,2,0) -> Sales Region Sulawesi - Maluku Team | J13: =VLOOKUP(C13,'Sales Team'!A$1:D$6,4,0) -> Corporate Negotiate/Patnership Contract | K13: =VLOOKUP(B13,'Patner Store'!A$1:F$51,2,0) -> SportMania Store | L13: =VLOOKUP(B13,'Patner Store'!A$1:F$51,3,0) -> Retail | M13: =VLOOKUP(B13,'Patner Store'!A$1:F$51,4,0) -> North Maluku | N13: =VLOOKUP(B13,'Patner Store'!A$1:F$51,5,0) -> North Maluku
A14: SO0013 | B14: PS0050 | C14: ST0004 | D14: 43848 | E14: Sulawesi, Maluku, North Maluku | F14: CREDIT | G14: 637102960 | I14: =VLOOKUP(C14,'Sales Team'!A$1:C$6,2,0) -> Sales Region Sulawesi - Maluku Team | J14: =VLOOKUP(C14,'Sales Team'!A$1:D$6,4,0) -> Corporate Negotiate/Patnership Contract | K14: =VLOOKUP(B14,'Patner Store'!A$1:F$51,2,0) -> Toko Peralatan Olahraga | L14: =VLOOKUP(B14,'Patner Store'!A$1:F$51,3,0) -> Retail | M14: =VLOOKUP(B14,'Patner Store'!A$1:F$51,4,0) -> Maluku | N14: =VLOOKUP(B14,'Patner Store'!A$1:F$51,5,0) -> Maluku
A15: SO0014 | B15: PS0032 | C15: ST0004 | D15: 43849 | E15: Sulawesi, Maluku, North Maluku | F15: CREDIT | G15: 290103980 | I15: =VLOOKUP(C15,'Sales Team'!A$1:C$6,2,0) -> Sales Region Sulawesi - Maluku Team | J15: =VLOOKUP(C15,'Sales Team'!A$1:D$6,4,0) -> Corporate Negotiate/Patnership Contract | K15: =VLOOKUP(B15,'Patner Store'!A$1:F$51,2,0) -> Toko Idola Olahraga | L15: =VLOOKUP(B15,'Patner Store'!A$1:F$51,3,0) -> Retail | M15: =VLOOKUP(B15,'Patner Store'!A$1:F$51,4,0) -> Sulawesi | N15: =VLOOKUP(B15,'Patner Store'!A$1:F$51,5,0) -> North Sulawesi
A16: SO0015 | B16: PS0014 | C16: ST0003 | D16: 43850 | E16: Sumatera & Kalimantan | F16: CREDIT | G16: 644706190 | H16: transaction as agreed with the vendor | I16: =VLOOKUP(C16,'Sales Team'!A$1:C$6,2,0) -> Sales Sumatera -Kalimantan Region Team | J16: =VLOOKUP(C16,'Sales Team'!A$1:D$6,4,0) -> OnlineMarketing/Corporate Negotiate/Patnership Contract | K16: =VLOOKUP(B16,'Patner Store'!A$1:F$51,2,0) -> Sport Hub Medan | L16: =VLOOKUP(B16,'Patner Store'!A$1:F$51,3,0) -> Distributor | M16: =VLOOKUP(B16,'Patner Store'!A$1:F$51,4,0) -> Sumatera | N16: =VLOOKUP(B16,'Patner Store'!A$1:F$51,5,0) -> North Sumatera
A17: SO0016 | B17: PS0008 | C17: ST0004 | D17: 43850 | E17: Sulawesi, Maluku, North Maluku | F17: CASH | G17: 248020740 | H17: Partner Store canceled the order | I17: =VLOOKUP(C17,'Sales Team'!A$1:C$6,2,0) -> Sales Region Sulawesi - Maluku Team | J17: =VLOOKUP(C17,'Sales Team'!A$1:D$6,4,0) -> Corporate Negotiate/Patnership Contract | K17: =VLOOKUP(B17,'Patner Store'!A$1:F$51,2,0) -> Amanah Sport | L17: =VLOOKUP(B17,'Patner Store'!A$1:F$51,3,0) -> Retail | M17: =VLOOKUP(B17,'Patner Store'!A$1:F$51,4,0) -> Sulawesi | N17: =VLOOKUP(B17,'Patner Store'!A$1:F$51,5,0) -> North Sulawesi
A18: SO0017 | B18: PS0013 | C18: ST0001 | D18: 43853 | E18: Jakarta | F18: CREDIT | G18: 688063360 | I18: =VLOOKUP(C18,'Sales Team'!A$1:C$6,2,0) -> Online Sales Team | J18: =VLOOKUP(C18,'Sales Team'!A$1:D$6,4,0) -> OnlineMarketing | K18: =VLOOKUP(B18,'Patner Store'!A$1:F$51,2,0) -> Playing Outdoor | L18: =VLOOKUP(B18,'Patner Store'!A$1:F$51,3,0) -> Retail | M18: =VLOOKUP(B18,'Patner Store'!A$1:F$51,4,0) -> Java | N18: =VLOOKUP(B18,'Patner Store'!A$1:F$51,5,0) -> Jakarta
A19: SO0018 | B19: PS0039 | C19: ST0003 | D19: 43853 | E19: Sumatera & Kalimantan | F19: CASH | G19: 44061600 | I19: =VLOOKUP(C19,'Sales Team'!A$1:C$6,2,0) -> Sales Sumatera -Kalimantan Region Team | J19: =VLOOKUP(C19,'Sales Team'!A$1:D$6,4,0) -> OnlineMarketing/Corporate Negotiate/Patnership Contract | K19: =VLOOKUP(B19,'Patner Store'!A$1:F$51,2,0) -> Surya Sport | L19: =VLOOKUP(B19,'Patner Store'!A$1:F$51,3,0) -> Retail | M19: =VLOOKUP(B19,'Patner Store'!A$1:F$51,4,0) -> Kalimantan | N19: =VLOOKUP(B19,'Patner Store'!A$1:F$51,5,0) -> South Kalimantan
A20: SO0019 | B20: PS0020 | C20: ST0004 | D20: 43854 | E20: Sulawesi, Maluku, North Maluku | F20: CREDIT | G20: 301033270 | I20: =VLOOKUP(C20,'Sales Team'!A$1:C$6,2,0) -> Sales Region Sulawesi - Maluku Team | J20: =VLOOKUP(C20,'Sales Team'!A$1:D$6,4,0) -> Corporate Negotiate/Patnership Contract | K20: =VLOOKUP(B20,'Patner Store'!A$1:F$51,2,0) -> Barokah Olahraga Shop | L20: =VLOOKUP(B20,'Patner Store'!A$1:F$51,3,0) -> Retail | M20: =VLOOKUP(B20,'Patner Store'!A$1:F$51,4,0) -> Sulawesi | N20: =VLOOKUP(B20,'Patner Store'!A$1:F$51,5,0) -> North Sulawesi
A21: SO0020 | B21: PS0019 | C21: ST0005 | D21: 43856 | E21: Bali, East & West Nusa Tenggara | F21: CASH | G21: 70487380 | I21: =VLOOKUP(C21,'Sales Team'!A$1:C$6,2,0) -> Sales Region Bali - Nusa Tenggara Team | J21: =VLOOKUP(C21,'Sales Team'!A$1:D$6,4,0) -> Corporate Negotiate/Patnership Contract | K21: =VLOOKUP(B21,'Patner Store'!A$1:F$51,2,0) -> Toko olahraga Pantai | L21: =VLOOKUP(B21,'Patner Store'!A$1:F$51,3,0) -> Retail | M21: =VLOOKUP(B21,'Patner Store'!A$1:F$51,4,0) -> Nusa Tenggara | N21: =VLOOKUP(B21,'Patner Store'!A$1:F$51,5,0) -> East Nusa Tenggara
A22: SO0021 | B22: PS0037 | C22: ST0002 | D22: 43856 | E22: Java | F22: CASH | G22: 219754110 | I22: =VLOOKUP(C22,'Sales Team'!A$1:C$6,2,0) -> Sales Java Region Team | J22: =VLOOKUP(C22,'Sales Team'!A$1:D$6,4,0) -> OnlineMarketing/Corporate Negotiate/Patnership Contract | K22: =VLOOKUP(B22,'Patner Store'!A$1:F$51,2,0) -> Toko Joko Sport | L22: =VLOOKUP(B22,'Patner Store'!A$1:F$51,3,0) -> Retail | M22: =VLOOKUP(B22,'Patner Store'!A$1:F$51,4,0) -> Java | N22: =VLOOKUP(B22,'Patner Store'!A$1:F$51,5,0) -> East Java
A23: SO0022 | B23: PS0018 | C23: ST0002 | D23: 43856 | E23: Java | F23: CREDIT | G23: 473835924 | H23: The product is unavailable from the vendor or there has been a product replacement | I23: =VLOOKUP(C23,'Sales Team'!A$1:C$6,2,0) -> Sales Java Region Team | J23: =VLOOKUP(C23,'Sales Team'!A$1:D$6,4,0) -> OnlineMarketing/Corporate Negotiate/Patnership Contract | K23: =VLOOKUP(B23,'Patner Store'!A$1:F$51,2,0) -> Sport Jogja City | L23: =VLOOKUP(B23,'Patner Store'!A$1:F$51,3,0) -> Distributor | M23: =VLOOKUP(B23,'Patner Store'!A$1:F$51,4,0) -> Java | N23: =VLOOKUP(B23,'Patner Store'!A$1:F$51,5,0) -> Jogjakarta
A24: SO0023 | B24: PS0013 | C24: ST0001 | D24: 43857 | E24: Jakarta | F24: CASH | G24: 177937976 | I24: =VLOOKUP(C24,'Sales Team'!A$1:C$6,2,0) -> Online Sales Team | J24: =VLOOKUP(C24,'Sales Team'!A$1:D$6,4,0) -> OnlineMarketing | K24: =VLOOKUP(B24,'Patner Store'!A$1:F$51,2,0) -> Playing Outdoor | L24: =VLOOKUP(B24,'Patner Store'!A$1:F$51,3,0) -> Retail | M24: =VLOOKUP(B24,'Patner Store'!A$1:F$51,4,0) -> Java | N24: =VLOOKUP(B24,'Patner Store'!A$1:F$51,5,0) -> Jakarta
A25: SO0024 | B25: PS0040 | C25: ST0003 | D25: 43859 | E25: Sumatera & Kalimantan | F25: CASH | G25: 43468350 | I25: =VLOOKUP(C25,'Sales Team'!A$1:C$6,2,0) -> Sales Sumatera -Kalimantan Region Team | J25: =VLOOKUP(C25,'Sales Team'!A$1:D$6,4,0) -> OnlineMarketing/Corporate Negotiate/Patnership Contract | K25: =VLOOKUP(B25,'Patner Store'!A$1:F$51,2,0) -> Olahraga Gemilang | L25: =VLOOKUP(B25,'Patner Store'!A$1:F$51,3,0) -> Retail | M25: =VLOOKUP(B25,'Patner Store'!A$1:F$51,4,0) -> Kalimantan | N25: =VLOOKUP(B25,'Patner Store'!A$1:F$51,5,0) -> Central Kalimantan
A26: SO0025 | B26: PS0034 | C26: ST0001 | D26: 43860 | E26: Jakarta | F26: CASH | G26: 72692150 | I26: =VLOOKUP(C26,'Sales Team'!A$1:C$6,2,0) -> Online Sales Team | J26: =VLOOKUP(C26,'Sales Team'!A$1:D$6,4,0) -> OnlineMarketing | K26: =VLOOKUP(B26,'Patner Store'!A$1:F$51,2,0) -> Active Sport | L26: =VLOOKUP(B26,'Patner Store'!A$1:F$51,3,0) -> Retail | M26: =VLOOKUP(B26,'Patner Store'!A$1:F$51,4,0) -> Java | N26: =VLOOKUP(B26,'Patner Store'!A$1:F$51,5,0) -> Jakarta
A27: SO0026 | B27: PS0021 | C27: ST0001 | D27: 43861 | E27: Jakarta | F27: CASH | G27: 249589510 | H27: The product is unavailable from the vendor or there has been a product replacement | I27: =VLOOKUP(C27,'Sales Team'!A$1:C$6,2,0) -> Online Sales Team | J27: =VLOOKUP(C27,'Sales Team'!A$1:D$6,4,0) -> OnlineMarketing | K27: =VLOOKUP(B27,'Patner Store'!A$1:F$51,2,0) -> SportArt88 | L27: =VLOOKUP(B27,'Patner Store'!A$1:F$51,3,0) -> Retail | M27: =VLOOKUP(B27,'Patner Store'!A$1:F$51,4,0) -> Java | N27: =VLOOKUP(B27,'Patner Store'!A$1:F$51,5,0) -> Jakarta
A28: SO0027 | B28: PS0047 | C28: ST0001 | D28: 43861 | E28: Jakarta | F28: CREDIT | G28: 665340650 | H28: transaction as agreed with the vendor | I28: =VLOOKUP(C28,'Sales Team'!A$1:C$6,2,0) -> Online Sales Team | J28: =VLOOKUP(C28,'Sales Team'!A$1:D$6,4,0) -> OnlineMarketing | K28: =VLOOKUP(B28,'Patner Store'!A$1:F$51,2,0) -> Power Play | L28: =VLOOKUP(B28,'Patner Store'!A$1:F$51,3,0) -> Retail | M28: =VLOOKUP(B28,'Patner Store'!A$1:F$51,4,0) -> Java | N28: =VLOOKUP(B28,'Patner Store'!A$1:F$51,5,0) -> Jakarta
A29: SO0028 | B29: PS0035 | C29: ST0004 | D29: 43866 | E29: Sulawesi, Maluku, North Maluku | F29: CASH | G29: 110695360 | H29: Partner Store canceled the order | I29: =VLOOKUP(C29,'Sales Team'!A$1:C$6,2,0) -> Sales Region Sulawesi - Maluku Team | J29: =VLOOKUP(C29,'Sales Team'!A$1:D$6,4,0) -> Corporate Negotiate/Patnership Contract | K29: =VLOOKUP(B29,'Patner Store'!A$1:F$51,2,0) -> Toko Olahraga Lengkap | L29: =VLOOKUP(B29,'Patner Store'!A$1:F$51,3,0) -> Retail | M29: =VLOOKUP(B29,'Patner Store'!A$1:F$51,4,0) -> Maluku | N29: =VLOOKUP(B29,'Patner Store'!A$1:F$51,5,0) -> Maluku
A30: SO0029 | B30: PS0028 | C30: ST0005 | D30: 43866 | E30: Bali, East & West Nusa Tenggara | F30: CASH | G30: 48219680 | I30: =VLOOKUP(C30,'Sales Team'!A$1:C$6,2,0) -> Sales Region Bali - Nusa Tenggara Team | J30: =VLOOKUP(C30,'Sales Team'!A$1:D$6,4,0) -> Corporate Negotiate/Patnership Contract | K30: =VLOOKUP(B30,'Patner Store'!A$1:F$51,2,0) -> Toko SportNesia | L30: =VLOOKUP(B30,'Patner Store'!A$1:F$51,3,0) -> Retail | M30: =VLOOKUP(B30,'Patner Store'!A$1:F$51,4,0) -> Nusa Tenggara | N30: =VLOOKUP(B30,'Patner Store'!A$1:F$51,5,0) -> East Nusa Tenggara
A31: SO0030 | B31: PS0022 | C31: ST0004 | D31: 43868 | E31: Sulawesi, Maluku, North Maluku | F31: CASH | G31: 80974010 | I31: =VLOOKUP(C31,'Sales Team'!A$1:C$6,2,0) -> Sales Region Sulawesi - Maluku Team | J31: =VLOOKUP(C31,'Sales Team'!A$1:D$6,4,0) -> Corporate Negotiate/Patnership Contract | K31: =VLOOKUP(B31,'Patner Store'!A$1:F$51,2,0) -> Sport Kita Store | L31: =VLOOKUP(B31,'Patner Store'!A$1:F$51,3,0) -> Retail | M31: =VLOOKUP(B31,'Patner Store'!A$1:F$51,4,0) -> North Maluku | N31: =VLOOKUP(B31,'Patner Store'!A$1:F$51,5,0) -> North Maluku
A32: SO0031 | B32: PS0007 | C32: ST0001 | D32: 43874 | E32: Jakarta | F32: CASH | G32: 21634158 | H32: The transaction agreement has undergone changes | I32: =VLOOKUP(C32,'Sales Team'!A$1:C$6,2,0) -> Online Sales Team | J32: =VLOOKUP(C32,'Sales Team'!A$1:D$6,4,0) -> OnlineMarketing | K32: =VLOOKUP(B32,'Patner Store'!A$1:F$51,2,0) -> Twinsport.com | L32: =VLOOKUP(B32,'Patner Store'!A$1:F$51,3,0) -> Retail | M32: =VLOOKUP(B32,'Patner Store'!A$1:F$51,4,0) -> Java | N32: =VLOOKUP(B32,'Patner Store'!A$1:F$51,5,0) -> Jakarta
A33: SO0032 | B33: PS0010 | C33: ST0001 | D33: 43875 | E33: Jakarta | F33: CASH | G33: 38254350 | I33: =VLOOKUP(C33,'Sales Team'!A$1:C$6,2,0) -> Online Sales Team | J33: =VLOOKUP(C33,'Sales Team'!A$1:D$6,4,0) -> OnlineMarketing | K33: =VLOOKUP(B33,'Patner Store'!A$1:F$51,2,0) -> WorldSport.com | L33: =VLOOKUP(B33,'Patner Store'!A$1:F$51,3,0) -> Retail | M33: =VLOOKUP(B33,'Patner Store'!A$1:F$51,4,0) -> Java | N33: =VLOOKUP(B33,'Patner Store'!A$1:F$51,5,0) -> Jakarta
A34: SO0033 | B34: PS0012 | C34: ST0003 | D34: 43875 | E34: Sumatera & Kalimantan | F34: CREDIT | G34: 274768110 | H34: The transaction agreement has undergone changes | I34: =VLOOKUP(C34,'Sales Team'!A$1:C$6,2,0) -> Sales Sumatera -Kalimantan Region Team | J34: =VLOOKUP(C34,'Sales Team'!A$1:D$6,4,0) -> OnlineMarketing/Corporate Negotiate/Patnership Contract | K34: =VLOOKUP(B34,'Patner Store'!A$1:F$51,2,0) -> Adi Shop | L34: =VLOOKUP(B34,'Patner Store'!A$1:F$51,3,0) -> Retail | M34: =VLOOKUP(B34,'Patner Store'!A$1:F$51,4,0) -> Kalimantan | N34: =VLOOKUP(B34,'Patner Store'!A$1:F$51,5,0) -> South Kalimantan
A35: SO0034 | B35: PS0001 | C35: ST0005 | D35: 43876 | E35: Bali, East & West Nusa Tenggara | F35: CASH | G35: 156249110 | I35: =VLOOKUP(C35,'Sales Team'!A$1:C$6,2,0) -> Sales Region Bali - Nusa Tenggara Team | J35: =VLOOKUP(C35,'Sales Team'!A$1:D$6,4,0) -> Corporate Negotiate/Patnership Contract | K35: =VLOOKUP(B35,'Patner Store'!A$1:F$51,2,0) -> Sport Nation | L35: =VLOOKUP(B35,'Patner Store'!A$1:F$51,3,0) -> Distributor | M35: =VLOOKUP(B35,'Patner Store'!A$1:F$51,4,0) -> Bali | N35: =VLOOKUP(B35,'Patner Store'!A$1:F$51,5,0) -> Bali
A36: SO0035 | B36: PS0033 | C36: ST0005 | D36: 43877 | E36: Bali, East & West Nusa Tenggara | F36: CREDIT | G36: 473491910 | I36: =VLOOKUP(C36,'Sales Team'!A$1:C$6,2,0) -> Sales Region Bali - Nusa Tenggara Team | J36: =VLOOKUP(C36,'Sales Team'!A$1:D$6,4,0) -> Corporate Negotiate/Patnership Contract | K36: =VLOOKUP(B36,'Patner Store'!A$1:F$51,2,0) -> Toko Olahraga NTT | L36: =VLOOKUP(B36,'Patner Store'!A$1:F$51,3,0) -> Retail | M36: =VLOOKUP(B36,'Patner Store'!A$1:F$51,4,0) -> Nusa Tenggara | N36: =VLOOKUP(B36,'Patner Store'!A$1:F$51,5,0) -> East Nusa Tenggara
A37: SO0036 | B37: PS0034 | C37: ST0001 | D37: 43878 | E37: Jakarta | F37: CREDIT | G37: 376525700 | I37: =VLOOKUP(C37,'Sales Team'!A$1:C$6,2,0) -> Online Sales Team | J37: =VLOOKUP(C37,'Sales Team'!A$1:D$6,4,0) -> OnlineMarketing | K37: =VLOOKUP(B37,'Patner Store'!A$1:F$51,2,0) -> Active Sport | L37: =VLOOKUP(B37,'Patner Store'!A$1:F$51,3,0) -> Retail | M37: =VLOOKUP(B37,'Patner Store'!A$1:F$51,4,0) -> Java | N37: =VLOOKUP(B37,'Patner Store'!A$1:F$51,5,0) -> Jakarta
A38: SO0037 | B38: PS0028 | C38: ST0005 | D38: 43881 | E38: Bali, East & West Nusa Tenggara | F38: CREDIT | G38: 1038581420 | H38: transaction as agreed with the vendor | I38: =VLOOKUP(C38,'Sales Team'!A$1:C$6,2,0) -> Sales Region Bali - Nusa Tenggara Team | J38: =VLOOKUP(C38,'Sales Team'!A$1:D$6,4,0) -> Corporate Negotiate/Patnership Contract | K38: =VLOOKUP(B38,'Patner Store'!A$1:F$51,2,0) -> Toko SportNesia | L38: =VLOOKUP(B38,'Patner Store'!A$1:F$51,3,0) -> Retail | M38: =VLOOKUP(B38,'Patner Store'!A$1:F$51,4,0) -> Nusa Tenggara | N38: =VLOOKUP(B38,'Patner Store'!A$1:F$51,5,0) -> East Nusa Tenggara
A39: SO0038 | B39: PS0036 | C39: ST0005 | D39: 43882 | E39: Bali, East & West Nusa Tenggara | F39: CASH | G39: 130531820 | I39: =VLOOKUP(C39,'Sales Team'!A$1:C$6,2,0) -> Sales Region Bali - Nusa Tenggara Team | J39: =VLOOKUP(C39,'Sales Team'!A$1:D$6,4,0) -> Corporate Negotiate/Patnership Contract | K39: =VLOOKUP(B39,'Patner Store'!A$1:F$51,2,0) -> Nusantara Sport | L39: =VLOOKUP(B39,'Patner Store'!A$1:F$51,3,0) -> Retail | M39: =VLOOKUP(B39,'Patner Store'!A$1:F$51,4,0) -> Nusa Tenggara | N39: =VLOOKUP(B39,'Patner Store'!A$1:F$51,5,0) -> West Nusa Tenggara
A40: SO0039 | B40: PS0013 | C40: ST0001 | D40: 43883 | E40: Jakarta | F40: CREDIT | G40: 1115480621 | H40: transaction as agreed with the vendor | I40: =VLOOKUP(C40,'Sales Team'!A$1:C$6,2,0) -> Online Sales Team | J40: =VLOOKUP(C40,'Sales Team'!A$1:D$6,4,0) -> OnlineMarketing | K40: =VLOOKUP(B40,'Patner Store'!A$1:F$51,2,0) -> Playing Outdoor | L40: =VLOOKUP(B40,'Patner Store'!A$1:F$51,3,0) -> Retail | M40: =VLOOKUP(B40,'Patner Store'!A$1:F$51,4,0) -> Java | N40: =VLOOKUP(B40,'Patner Store'!A$1:F$51,5,0) -> Jakarta
...

Sheet Product & Category Analysis
A1: Category Performance Overview
A2: Row Labels | B2: Total Revenue by Category | C2: Quantity Orders | D2: Orders each category | N2: Row Labels | O2: Orders each category | S2: Row Labels | T2: Quantity Orders
A3: Basketball | B3: 5778248850 | C3: 14162 | D3: 159 | N3: Basketball | O3: 159 | S3: Basketball | T3: 14162
A4: Bicycle | B4: 109802799810 | C4: 31926 | D4: 358 | N4: Bicycle | O4: 358 | S4: Bicycle | T4: 31926
A5: Billiard | B5: 13496671580 | C5: 27343 | D5: 332 | N5: Billiard | O5: 332 | S5: Billiard | T5: 27343
A6: Fishing Equipment | B6: 3419283660 | C6: 29794 | D6: 335 | N6: Fishing Equipment | O6: 335 | S6: Fishing Equipment | T6: 29794
A7: Futsal | B7: 3066297420 | C7: 13481 | D7: 165 | N7: Futsal | O7: 165 | S7: Futsal | T7: 13481
A8: Golf | B8: 69033801500 | C8: 42771 | D8: 482 | N8: Golf | O8: 482 | S8: Golf | T8: 42771
A9: Gym & Fitness | B9: 84120889453 | C9: 91209 | D9: 1024 | N9: Gym & Fitness | O9: 1024 | S9: Gym & Fitness | T9: 91209
A10: Hiking & Camping | B10: 6003969090 | C10: 30888 | D10: 355 | N10: Hiking & Camping | O10: 355 | S10: Hiking & Camping | T10: 30888
A11: Outdoors Sport | B11: 2047939440 | C11: 16032 | D11: 182 | N11: Outdoors Sport | O11: 182 | S11: Outdoors Sport | T11: 16032
A12: Grand Total | B12: 296769900803 | C12: 297606 | D12: 3392 | N12: Grand Total | O12: 3392 | S12: Grand Total | T12: 297606
A15: Revenue Contribution %
A16: Category | B16: Revenue | C16: Contribution%
A17: Basketball | B17: 5778248850 | C17: =GETPIVOTDATA("Total Revenue by Category",$A$2,"Category","Basketball")/GETPIVOTDATA("Total Revenue by Category",$A$2) -> 0.019470468
A18: Bicycle | B18: 109802799810 | C18: =GETPIVOTDATA("Total Revenue by Category",$A$2,"Category","Bicycle")/GETPIVOTDATA("Total Revenue by Category",$A$2) -> 0.36999305
A19: Billiard | B19: 13496671580 | C19: =GETPIVOTDATA("Total Revenue by Category",$A$2,"Category","Billiard")/GETPIVOTDATA("Total Revenue by Category",$A$2) -> 0.045478573
A20: Fishing Equipment | B20: 3419283660 | C20: =GETPIVOTDATA("Total Revenue by Category",$A$2,"Category","Fishing Equipment")/GETPIVOTDATA("Total Revenue by Category",$A$2) -> 0.011521666
A21: Futsal | B21: 3066297420 | C21: =GETPIVOTDATA("Total Revenue by Category",$A$2,"Category","Futsal")/GETPIVOTDATA("Total Revenue by Category",$A$2) -> 0.010332239
A22: Golf | B22: 69033801500 | C22: =GETPIVOTDATA("Total Revenue by Category",$A$2,"Category","Golf")/GETPIVOTDATA("Total Revenue by Category",$A$2) -> 0.23261726
A23: Gym & Fitness | B23: 84120889453 | C23: =GETPIVOTDATA("Total Revenue by Category",$A$2,"Category","Gym & Fitness")/GETPIVOTDATA("Total Revenue by Category",$A$2) -> 0.28345492
A24: Hiking & Camping | B24: 6003969090 | C24: =GETPIVOTDATA("Total Revenue by Category",$A$2,"Category","Hiking & Camping")/GETPIVOTDATA("Total Revenue by Category",$A$2) -> 0.020231058
A25: Outdoors Sport | B25: 2047939440 | C25: =GETPIVOTDATA("Total Revenue by Category",$A$2,"Category","Outdoors Sport")/GETPIVOTDATA("Total Revenue by Category",$A$2) -> 0.0069007653
A38: Top Products within Categories
A39: Row Labels | B39: Sum of ItemTotal | C39: Row Labels | D39: Sum of ItemTotal
A40: Bicycle | B40: 109802799810 | C40: Mountain Bike | D40: 31610057430
A41: Road Bike | B41: 78192742380 | C41: Treadmill | D41: 31829133590
A42: Mountain Bike | B42: 31610057430 | C42: Bench Press | D42: 35684926500
A43: Gym & Fitness | B43: 82515697090 | C43: Stick Golf Bag | D43: 39988768000
A44: Bench Press | B44: 35684926500 | C44: Road Bike | D44: 78192742380
A45: Dumbell Set | B45: 7134274280 | C45: Grand Total | D45: 217305627900
A46: Heavy bag | B46: 4940433960
A47: Pull Up Bar | B47: 2926928760
A48: Treadmill | B48: 31829133590
A49: Golf | B49: 69033801500
A50: 1 set Golf Ball | B50: 2476555950
A51: Stick Golf Bag | B51: 39988768000
A52: Stick Golf Wedge | B52: 26568477550
A53: Billiard | B53: 13496671580
A54: Stick Billiard | B54: 10971071580
...

Sheet Order Item
A1: SalesOrderID | B1: OrderDate | C1: ProductID | D1: QuantityOrder | E1: ItemTotal | F1: OrderItemID | G1: ProductName | H1: Category | I1: ProductName | J1: QuantityOrder | K1: SalesTeamName | L1: Prospect per Sales Team | M1: Patner Type
A2: SO0001 | B2: =VLOOKUP(A2,'Sales Order'!A$1:D$1029,4,0) -> 43832 | C2: PD0002 | D2: 99 | E2: 1841400 | F2: SO0001-PD0002 | G2: =VLOOKUP(C2,Product!A$1:D$21,3,0) -> Fishing soft lure | H2: =VLOOKUP(C2,Product!A$1:D$21,4,0) -> Fishing Equipment | I2: Fishing soft lure | J2: 99 | K2: =VLOOKUP(A2,'Sales Order'!A$2:I$1029,9,0) -> Sales Sumatera -Kalimantan Region Team | M2: =VLOOKUP(A2,'Sales Order'!A$1:L$1029,12,0) -> Retail
A3: SO0001 | B3: =VLOOKUP(A3,'Sales Order'!A$1:D$1029,4,0) -> 43832 | C3: PD0015 | D3: 89 | E3: 9192276 | F3: SO0001-PD0015 | G3: =VLOOKUP(C3,Product!A$1:D$21,3,0) -> Abs Roller | H3: =VLOOKUP(C3,Product!A$1:D$21,4,0) -> Gym & Fitness | I3: Abs Roller | J3: 89 | K3: =VLOOKUP(A3,'Sales Order'!A$2:I$1029,9,0) -> Sales Sumatera -Kalimantan Region Team | M3: =VLOOKUP(A3,'Sales Order'!A$1:L$1029,12,0) -> Retail
A4: SO0001 | B4: =VLOOKUP(A4,'Sales Order'!A$1:D$1029,4,0) -> 43832 | C4: PD0011 | D4: 45 | E4: 93416400 | F4: SO0001-PD0011 | G4: =VLOOKUP(C4,Product!A$1:D$21,3,0) -> Mountain Bike | H4: =VLOOKUP(C4,Product!A$1:D$21,4,0) -> Bicycle | I4: Mountain Bike | J4: 45 | K4: =VLOOKUP(A4,'Sales Order'!A$2:I$1029,9,0) -> Sales Sumatera -Kalimantan Region Team | M4: =VLOOKUP(A4,'Sales Order'!A$1:L$1029,12,0) -> Retail
A5: SO0001 | B5: =VLOOKUP(A5,'Sales Order'!A$1:D$1029,4,0) -> 43832 | C5: PD0008 | D5: 72 | E5: 10191600 | F5: SO0001-PD0008 | G5: =VLOOKUP(C5,Product!A$1:D$21,3,0) -> Sunglasses | H5: =VLOOKUP(C5,Product!A$1:D$21,4,0) -> Outdoors Sport | I5: Sunglasses | J5: 72 | K5: =VLOOKUP(A5,'Sales Order'!A$2:I$1029,9,0) -> Sales Sumatera -Kalimantan Region Team | M5: =VLOOKUP(A5,'Sales Order'!A$1:L$1029,12,0) -> Retail
A6: SO0002 | B6: =VLOOKUP(A6,'Sales Order'!A$1:D$1029,4,0) -> 43832 | C6: PD0014 | D6: 77 | E6: 17063970 | F6: SO0002-PD0014 | G6: =VLOOKUP(C6,Product!A$1:D$21,3,0) -> 1 Set Futsalball | H6: =VLOOKUP(C6,Product!A$1:D$21,4,0) -> Futsal | I6: 1 Set Futsalball | J6: 77 | K6: =VLOOKUP(A6,'Sales Order'!A$2:I$1029,9,0) -> Sales Sumatera -Kalimantan Region Team | M6: =VLOOKUP(A6,'Sales Order'!A$1:L$1029,12,0) -> Retail
A7: SO0002 | B7: =VLOOKUP(A7,'Sales Order'!A$1:D$1029,4,0) -> 43832 | C7: PD0010 | D7: 92 | E7: 27807000 | F7: SO0002-PD0010 | G7: =VLOOKUP(C7,Product!A$1:D$21,3,0) -> Hiking Shoes | H7: =VLOOKUP(C7,Product!A$1:D$21,4,0) -> Hiking & Camping | I7: Hiking Shoes | J7: 92 | K7: =VLOOKUP(A7,'Sales Order'!A$2:I$1029,9,0) -> Sales Sumatera -Kalimantan Region Team | M7: =VLOOKUP(A7,'Sales Order'!A$1:L$1029,12,0) -> Retail
A8: SO0003 | B8: =VLOOKUP(A8,'Sales Order'!A$1:D$1029,4,0) -> 43833 | C8: PD0011 | D8: 142 | E8: 291430860 | F8: SO0003-PD0011 | G8: =VLOOKUP(C8,Product!A$1:D$21,3,0) -> Mountain Bike | H8: =VLOOKUP(C8,Product!A$1:D$21,4,0) -> Bicycle | I8: Mountain Bike | J8: 142 | K8: =VLOOKUP(A8,'Sales Order'!A$2:I$1029,9,0) -> Online Sales Team | M8: =VLOOKUP(A8,'Sales Order'!A$1:L$1029,12,0) -> Retail
A9: SO0003 | B9: =VLOOKUP(A9,'Sales Order'!A$1:D$1029,4,0) -> 43833 | C9: PD0018 | D9: 125 | E9: 51870000 | F9: SO0003-PD0018 | G9: =VLOOKUP(C9,Product!A$1:D$21,3,0) -> Dumbell Set | H9: =VLOOKUP(C9,Product!A$1:D$21,4,0) -> Gym & Fitness | I9: Dumbell Set | J9: 125 | K9: =VLOOKUP(A9,'Sales Order'!A$2:I$1029,9,0) -> Online Sales Team | M9: =VLOOKUP(A9,'Sales Order'!A$1:L$1029,12,0) -> Retail
A10: SO0003 | B10: =VLOOKUP(A10,'Sales Order'!A$1:D$1029,4,0) -> 43833 | C10: PD0010 | D10: 150 | E10: 44850000 | F10: SO0003-PD0010 | G10: =VLOOKUP(C10,Product!A$1:D$21,3,0) -> Hiking Shoes | H10: =VLOOKUP(C10,Product!A$1:D$21,4,0) -> Hiking & Camping | I10: Hiking Shoes | J10: 150 | K10: =VLOOKUP(A10,'Sales Order'!A$2:I$1029,9,0) -> Online Sales Team | M10: =VLOOKUP(A10,'Sales Order'!A$1:L$1029,12,0) -> Retail
A11: SO0003 | B11: =VLOOKUP(A11,'Sales Order'!A$1:D$1029,4,0) -> 43833 | C11: PD0008 | D11: 94 | E11: 12885520 | F11: SO0003-PD0008 | G11: =VLOOKUP(C11,Product!A$1:D$21,3,0) -> Sunglasses | H11: =VLOOKUP(C11,Product!A$1:D$21,4,0) -> Outdoors Sport | I11: Sunglasses | J11: 94 | K11: =VLOOKUP(A11,'Sales Order'!A$2:I$1029,9,0) -> Online Sales Team | M11: =VLOOKUP(A11,'Sales Order'!A$1:L$1029,12,0) -> Retail
A12: SO0003 | B12: =VLOOKUP(A12,'Sales Order'!A$1:D$1029,4,0) -> 43833 | C12: PD0012 | D12: 128 | E12: 671266560 | F12: SO0003-PD0012 | G12: =VLOOKUP(C12,Product!A$1:D$21,3,0) -> Road Bike | H12: =VLOOKUP(C12,Product!A$1:D$21,4,0) -> Bicycle | I12: Road Bike | J12: 128 | K12: =VLOOKUP(A12,'Sales Order'!A$2:I$1029,9,0) -> Online Sales Team | M12: =VLOOKUP(A12,'Sales Order'!A$1:L$1029,12,0) -> Retail
A13: SO0003 | B13: =VLOOKUP(A13,'Sales Order'!A$1:D$1029,4,0) -> 43833 | C13: PD0020 | D13: 101 | E13: 29503110 | F13: SO0003-PD0020 | G13: =VLOOKUP(C13,Product!A$1:D$21,3,0) -> Heavy bag | H13: =VLOOKUP(C13,Product!A$1:D$21,4,0) -> Gym & Fitness | I13: Heavy bag | J13: 101 | K13: =VLOOKUP(A13,'Sales Order'!A$2:I$1029,9,0) -> Online Sales Team | M13: =VLOOKUP(A13,'Sales Order'!A$1:L$1029,12,0) -> Retail
... A3393: SO1027 | B3393: =VLOOKUP(A3393,'Sales Order'!A$1:D$1029,4,0) -> 44914 | C3393: PD0007 | D3393: 121 | E3393: 367840000 | F3393: SO1027-PD0007 | G3393: =VLOOKUP(C3393,Product!A$1:D$21,3,0) -> Stick Golf Bag | H3393: =VLOOKUP(C3393,Product!A$1:D$21,4,0) -> Golf | I3393: Stick Golf Bag | J3393: 121 | K3393: =VLOOKUP(A3393,'Sales Order'!A$2:I$1029,9,0) -> Sales Region Bali - Nusa Tenggara Team | M3393: =VLOOKUP(A3393,'Sales Order'!A$1:L$1029,12,0) -> Retail
M3394: =VLOOKUP(A3394,'Sales Order'!A$1:L$1029,12,0) -> #N/A
M3395: =VLOOKUP(A3395,'Sales Order'!A$1:L$1029,12,0) -> #N/A
M3396: =VLOOKUP(A3396,'Sales Order'!A$1:L$1029,12,0) -> #N/A
M3397: =VLOOKUP(A3397,'Sales Order'!A$1:L$1029,12,0) -> #N/A
M3398: =VLOOKUP(A3398,'Sales Order'!A$1:L$1029,12,0) -> #N/A
M3399: =VLOOKUP(A3399,'Sales Order'!A$1:L$1029,12,0) -> #N/A
M3400: =VLOOKUP(A3400,'Sales Order'!A$1:L$1029,12,0) -> #N/A
M3401: =VLOOKUP(A3401,'Sales Order'!A$1:L$1029,12,0) -> #N/A
M3402: =VLOOKUP(A3402,'Sales Order'!A$1:L$1029,12,0) -> #N/A
M3403: =VLOOKUP(A3403,'Sales Order'!A$1:L$1029,12,0) -> #N/A
M3404: =VLOOKUP(A3404,'Sales Order'!A$1:L$1029,12,0) -> #N/A
M3405: =VLOOKUP(A3405,'Sales Order'!A$1:L$1029,12,0) -> #N/A
... M4000: =VLOOKUP(A4000,'Sales Order'!A$1:L$1029,12,0) -> #N/A

Sheet Vendor
A1: VendorID | B1: VendorName | C1: Address | D1: City | E1: Province | F1: Email | G1: Phone
A2: VD0001 | B2: PT.Aneka Olahraga | C2: Jl. Tanjong Priok No.23 | D2: North Jakarta | E2: Jakarta | F2: Anekasport@net.id | G2: +62 87 1651 6391
A3: VD0002 | B3: Sportspirit Inc | C3: Ubi Ave Street No.3 | D3: Singapore City | E3: Singapore | F3: sportspirit.co.id | G3: +65 8249 7112
A4: VD0003 | B4: PT.Fortune Sport | C4: Jl. Gajah Mada No.78 | D4: Central Jakarta | E4: Jakarta | F4: fortunesport.com | G4: +62 82 2497 3691

Sheet Product
A1: ProductID | B1: VendorID | C1: ProductName | D1: Category | E1: UnitSalesPrice | F1: UnitBuyPrice | G1: Quantity | H1: UOM | I1: DiscountProduct | J1: Product Description
A2: PD0001 | B2: VD0002 | C2: 1 Set Fishing Equipment | D2: Fishing Equipment | E2: 249000 | F2: 180000 | G2: 12547 | H2: Set | I2: 0.3 | J2: Joran, Reel, Tas, Senar, Mata kail, Stoper, Starlet
A3: PD0002 | B3: VD0002 | C3: Fishing soft lure | D3: Fishing Equipment | E3: 20000 | F3: 14000 | G3: 14769 | H3: Unit | I3: 0.1
A4: PD0003 | B4: VD0003 | C4: Stick Billiard | D4: Billiard | E4: 931000 | F4: 785000 | G4: 5654 | H4: Unit | I4: 0.2 | J4: Tip Size : 11.75mm, dan Length : 148 cm
A5: PD0004 | B5: VD0003 | C5: Stick Billiard Bag | D5: Billiard | E5: 220000 | F5: 175000 | G5: 3275 | H5: Unit | I5: 0.25
A6: PD0005 | B6: VD0001 | C6: Stick Golf Wedge | D6: Golf | E6: 2195000 | F6: 1785000 | G6: 3431 | H6: Unit | I6: 0.2 | J6: Degree : 52, 56, 60, 64
A7: PD0006 | B7: VD0001 | C7: 1 set Golf Ball | D7: Golf | E7: 209000 | F7: 195000 | G7: 8123 | H7: Set | I7: 0.2 | J7: 12 bola golf
A8: PD0007 | B8: VD0001 | C8: Stick Golf Bag | D8: Golf | E8: 3200000 | F8: 2800000 | G8: 2288 | H8: Unit | I8: 0.2
A9: PD0008 | B9: VD0002 | C9: Sunglasses | D9: Outdoors Sport | E9: 149000 | F9: 118000 | G9: 11023 | H9: Unit | I9: 0.15
A10: PD0009 | B10: VD0002 | C10: Tracking Pole | D10: Hiking & Camping | E10: 129000 | F10: 105000 | G10: 1418 | H10: Unit | I10: 0.15 | J10: Ukuran untuk Anak - anak : 100 cm, dan Dewasa : 125 com
A11: PD0010 | B11: VD0002 | C11: Hiking Shoes | D11: Hiking & Camping | E11: 325000 | F11: 250000 | G11: 3361 | H11: Unit | I11: 0.25 | J11: Size tersedia : 40/25.5cm - 44/29.5cm
A12: PD0011 | B12: VD0003 | C12: Mountain Bike | D12: Bicycle | E12: 2359000 | F12: 2000000 | G12: 2393 | H12: Unit | I12: 0.2 | J12: Warna : Hitam Merah, Grey Orange, Teal, Hitam biru
A13: PD0012 | B13: VD0003 | C13: Road Bike | D13: Bicycle | E13: 5639000 | F13: 4800000 | G13: 2710 | H13: Unit | I13: 0.2 | J13: Tipe Sepeda balap Performance dan All - around
A14: PD0013 | B14: VD0001 | C14: 1 Set Basketball | D14: Basketball | E14: 479000 | F14: 395000 | G14: 17561 | H14: Set | I14: 0.3 | J14: 5 Bola Basket
A15: PD0014 | B15: VD0001 | C15: 1 Set Futsalball | D15: Futsal | E15: 267000 | F15: 225000 | G15: 17743 | H15: Set | I15: 0.3 | J15: 5 Bola Futsal
A16: PD0015 | B16: VD0002 | C16: Abs Roller | D16: Gym & Fitness | E16: 135900 | F16: 95000 | G16: 3479 | H16: Unit | I16: 0.25
A17: PD0016 | B17: VD0002 | C17: Pull Up Bar | D17: Gym & Fitness | E17: 267000 | F17: 210000 | G17: 5101 | H17: Unit | I17: 0.25 | J17: Size : 80-130 cm
A18: PD0017 | B18: VD0002 | C18: Bench Press | D18: Gym & Fitness | E18: 2650000 | F18: 2200000 | G18: 2546 | H18: Unit | I18: 0.1 | J18: Dimensi : 142 x 110 x 108 cm
A19: PD0018 | B19: VD0002 | C19: Dumbell Set | D19: Gym & Fitness | E19: 532000 | F19: 485000 | G19: 11648 | H19: Unit | I19: 0.1 | J19: 2x 35cm (14") Stick Chrome, 1 pcs 152cm Stick, 6pcs Collar pengunci, 4pcs 1 kg plates, 2pcs 2 kg, 2pcs kg
A20: PD0019 | B20: VD0001 | C20: Treadmill | D20: Gym & Fitness | E20: 2549000 | F20: 2250000 | G20: 3106 | H20: Unit | I20: 0.25
A21: PD0020 | B21: VD0001 | C21: Heavy bag | D21: Gym & Fitness | E21: 321000 | F21: 275000 | G21: 3151 | H21: Unit | I21: 0.25

Sheet Patner Store
A1: PatnerStoreID | B1: PatnerStoreName | C1: PatnerType | D1: Region | E1: Province | F1: PatnerContactPhone
A2: PS0001 | B2: Sport Nation | C2: Distributor | D2: Bali | E2: Bali | F2: +62 837 3881 3393
A3: PS0002 | B3: TokoSport | C3: Retail | D3: Java | E3: East Java | F3: +62 843 0014 8341
A4: PS0003 | B4: Toko Gelora Sport | C4: Retail | D4: Kalimantan | E4: Central Kalimantan | F4: +62 856 3951 0850
A5: PS0004 | B5: Sport Line Indonesia | C5: Retail | D5: Java | E5: Jakarta | F5: +62 844 6558 9313
A6: PS0005 | B6: Sportworld | C6: Distributor | D6: Sulawesi | E6: South Sulawesi | F6: +62 834 8087 5084
A7: PS0006 | B7: Arena Sport Shop | C7: Retail | D7: Kalimantan | E7: Central Kalimantan | F7: +62 897 3528 4125
A8: PS0007 | B8: Twinsport.com | C8: Retail | D8: Java | E8: Jakarta | F8: +62 809 1899 6494
A9: PS0008 | B9: Amanah Sport | C9: Retail | D9: Sulawesi | E9: North Sulawesi | F9: +62 854 5164 5861
A10: PS0009 | B10: Olahraga Mall | C10: Distributor | D10: Sumatera | E10: South Sumatera | F10: +62 888 2771 3218
A11: PS0010 | B11: WorldSport.com | C11: Retail | D11: Java | E11: Jakarta | F11: +62 824 4696 3312
A12: PS0011 | B12: Atlethic Shop | C12: Retail | D12: Java | E12: East Java | F12: +62 878 0243 7778
... A51: PS0050 | B51: Toko Peralatan Olahraga | C51: Retail | D51: Maluku | E51: Maluku | F51: +62 888 9236 8417

Sheet PartnerStore Behaviour Analysis
A1: Partner Store Contribution Analysis
A2: Row Labels | B2: Sum of TotalOrderTransaction
A3: Toko Olahraga NTT | B3: 7028787634
A4: Mama Sport | B4: 7663872530
A5: Sport Line Indonesia | B5: 8044750889
A6: Destination Sport Store | B6: 8056757607
A7: Toko SportNesia | B7: 8236567341
A8: KakaSport | B8: 8237816158
A9: Salam Olahraga | B9: 8270107450
A10: SportMania Store | B10: 8349863320
A11: Sport Hub Medan | B11: 8466441644
A12: Toko Hidup Sehat | B12: 9429903378
A13: Grand Total | B13: 81784867951
A21: Partner Store | B21: Sum of TotalOrderTransaction | C21: Revenue Contribution(%)
A22: Active Sport | B22: 3900827045 | C22: =B22/B$72 -> 0.013144281
A23: Adi Shop | B23: 4293251970 | C23: =B23/B$72 -> 0.014466602
A24: Amanah Sport | B24: 3889569785 | C24: =B24/B$72 -> 0.013106349
A25: Arena Sport Shop | B25: 5580899608 | C25: =B25/B$72 -> 0.018805477
A26: Atlethic Shop | B26: 4952467699 | C26: =B26/B$72 -> 0.016687904
A27: Barokah Olahraga Shop | B27: 6026424376 | C27: =B27/B$72 -> 0.020306724
A28: Bebasport.com | B28: 3639962330 | C28: =B28/B$72 -> 0.012265268
A29: Destination Sport Store | B29: 8056757607 | C29: =B29/B$72 -> 0.027148163
A30: GilaSport.id | B30: 6012482646 | C30: =B30/B$72 -> 0.020259745
A31: Gudang Sport Center | B31: 4084865339 | C31: =B31/B$72 -> 0.013764419
A32: KakaSport | B32: 8237816158 | C32: =B32/B$72 -> 0.02775826
A33: Kartika Sport Center | B33: 5661787469 | C33: =B33/B$72 -> 0.019078038
... A71: WorldSport.com | B71: 5834510219 | C71: =B71/B$72 -> 0.019660047
A72: Grand Total | B72: 296769900803
A84: Partner Store Loyalty / Repeat Transaction
A85: Top Repeat Customers
A86: Row Labels | B86: Count of SalesOrder
A87: Atlethic Shop | B87: 24
A88: Toko Joko Sport | B88: 24
A89: Toko Hidup Sehat | B89: 24
A90: Olahraga Gemilang | B90: 25
A91: SportMania Store | B91: 25
A92: Surya Sport | B92: 25
A93: Sport Kita Store | B93: 25
A94: Barokah Olahraga Shop | B94: 26
A95: Destination Sport Store | B95: 27
...

Sheet Region & Sales Team Analysis
A1: Regional Performance Overview
A2: Row Labels | B2: Sum of TotalOrderTransaction | C2: Revenue Contribution
A3: Bali, East & West Nusa Tenggara | B3: 37219216848 | C3: =GETPIVOTDATA("TotalOrderTransaction",$A$2,"Region Sales Team","Bali, East & West Nusa Tenggara")/GETPIVOTDATA("TotalOrderTransaction",$A$2) -> 0.12541439
A4: Jakarta | B4: 52171345412 | C4: =GETPIVOTDATA("TotalOrderTransaction",$A$2,"Region Sales Team","Jakarta")/GETPIVOTDATA("TotalOrderTransaction",$A$2) -> 0.17579729
A5: Java | B5: 35941934604 | C5: =GETPIVOTDATA("TotalOrderTransaction",$A$2,"Region Sales Team","Java")/GETPIVOTDATA("TotalOrderTransaction",$A$2) -> 0.12111044
A6: Sulawesi, Maluku, North Maluku | B6: 103200235883 | C6: =GETPIVOTDATA("TotalOrderTransaction",$A$2,"Region Sales Team","Sulawesi, Maluku, North Maluku")/GETPIVOTDATA("TotalOrderTransaction",$A$2) -> 0.34774496
A7: Sumatera & Kalimantan | B7: 68237168056 | C7: =GETPIVOTDATA("TotalOrderTransaction",$A$2,"Region Sales Team","Sumatera & Kalimantan")/GETPIVOTDATA("TotalOrderTransaction",$A$2) -> 0.22993291
A8: Grand Total | B8: 296769900803
A28: Sales Team Performance & Trend Analysis
A29: Row Labels | B29: Sum of TotalOrderTransaction | E29: Row Labels | F29: Sum of QuantityOrder
A30: Online Sales Team | B30: 52171345412 | E30: Online Sales Team | F30: 55043
A31: Sales Java Region Team | B31: 35941934604 | E31: Sales Java Region Team | F31: 37129
A32: Sales Region Bali - Nusa Tenggara Team | B32: 37219216848 | E32: Sales Region Bali - Nusa Tenggara Team | F32: 35523
A33: Sales Region Sulawesi - Maluku Team | B33: 103200235883 | E33: Sales Region Sulawesi - Maluku Team | F33: 100928
A34: Sales Sumatera -Kalimantan Region Team | B34: 68237168056 | E34: Sales Sumatera -Kalimantan Region Team | F34: 68983
A35: Grand Total | B35: 296769900803 | E35: Grand Total | F35: 297606
A56: Multi-line Chart → Monthly Revenue Trend by Sales Team
A57: Sum of TotalOrderTransaction | B57: Column Labels
A58: Row Labels | B58: Online Sales Team | C58: Sales Java Region Team | D58: Sales Region Bali - Nusa Tenggara Team | E58: Sales Region Sulawesi - Maluku Team | F58: Sales Sumatera -Kalimantan Region Team | G58: Grand Total
A59: 2020 | B59: 24000030054 | C59: 12750281970 | D59: 15017127216 | E59: 37211661794 | F59: 22091747126 | G59: 111070848160
A60: 2021 | B60: 16306957968 | C60: 9530182325 | D60: 9559577587 | E60: 34397944631 | F60: 22165731721 | G60: 91960394232
A61: 2022 | B61: 11864357390 | C61: 13661470309 | D61: 12642512045 | E61: 31590629458 | F61: 23979689209 | G61: 93738658411
A62: Grand Total | B62: 52171345412 | C62: 35941934604 | D62: 37219216848 | E62: 103200235883 | F62: 68237168056 | G62: 296769900803
A83: Sales Promotion Method Analysis
A84: Revenue Contribution by Promotion Method
A85: Row Labels | B85: Sum of TotalOrderTransaction
A86: Corporate Negotiate/Patnership Contract | B86: 140419452731
A87: OnlineMarketing | B87: 52171345412
A88: OnlineMarketing/Corporate Negotiate/Patnership Contract | B88: 104179102660
A89: Grand Total | B89: 296769900803
A103: Prospect Contribution by Promotion Method
A104: Row Labels | B104: Sum of TotalProspect
A105: Corporate Negotiate/Patnership Contract | B105: 22
A106: OnlineMarketing | B106: 10
A107: OnlineMarketing/Corporate Negotiate/Patnership Contract | B107: 18
A108: Grand Total | B108: 50
A124: Conversion / Efficiency Analysis
A125: Row Labels | B125: Sum of TotalProspect | C125: Revenue Per Prospect
A126: Corporate Negotiate/Patnership Contract | B126: 22 | C126: 6.3827024e+09
A127: OnlineMarketing | B127: 10 | C127: 5.2171345e+09
...

Sheet Sales Team
A1: SalesTeamID | B1: SalesTeamName | C1: SalesTeamRegion | D1: SalesPromotionMethods | E1: TotalProspect
A2: ST0001 | B2: Online Sales Team | C2: Jakarta | D2: OnlineMarketing | E2: 10
A3: ST0002 | B3: Sales Java Region Team | C3: Java | D3: OnlineMarketing/Corporate Negotiate/Patnership Contract | E3: 6
A4: ST0003 | B4: Sales Sumatera -Kalimantan Region Team | C4: Sumatera & Kalimantan | D4: OnlineMarketing/Corporate Negotiate/Patnership Contract | E4: 12
A5: ST0004 | B5: Sales Region Sulawesi - Maluku Team | C5: Sulawesi, Maluku, North Maluku | D5: Corporate Negotiate/Patnership Contract | E5: 16
A6: ST0005 | B6: Sales Region Bali - Nusa Tenggara Team | C6: Bali, East & West Nusa Tenggara | D6: Corporate Negotiate/Patnership Contract | E6: 6

Sheet Invoice
A1: InvoiceID | B1: SalesOrderID | C1: ShipmentType | D1: WarehouseLocation | E1: TermsofPayment | F1: ShippingCost | G1: Taxes | H1: TotalDue
A2: IV0001 | B2: SO0001 | C2: Cargo | D2: Central Kalimantan | E2: COD | F2: 808800 | G2: 0.11 | H2: 1.2806106e+08
A3: IV0002 | B3: SO0002 | C3: Cargo | D3: South Kalimantan | E3: COD | F3: 808800 | G3: 0.11 | H3: 50615577
A4: IV0003 | B4: SO0003 | C4: Reguler | D4: Jakarta | E4: NET60 | F4: 8088 | G4: 0.11 | H4: 1.2230128e+09
A5: IV0004 | B5: SO0004 | C5: Cargo | D5: South Kalimantan | E5: COD | F5: 808800 | G5: 0.11 | H5: 12683633
A6: IV0005 | B6: SO0005 | C6: Reguler | D6: Jakarta | E6: NET60 | F6: 8088 | G6: 0.11 | H6: 278129688
A7: IV0006 | B7: SO0006 | C7: Cargo | D7: South Kalimantan | E7: COD | F7: 808800 | G7: 0.11 | H7: 13317878
A8: IV0007 | B8: SO0007 | C8: Reguler | D8: Jakarta | E8: NET90 | F8: 8088 | G8: 0.11 | H8: 4.7400892e+08
A9: IV0008 | B9: SO0008 | C9: Cargo | D9: West Nusa Tenggara | E9: NET90 | F9: 556050 | G9: 0.11 | H9: 6.8222585e+08
A10: IV0009 | B10: SO0009 | C10: Reguler | D10: East Java | E10: CBD | F10: 32352 | G10: 0.11 | H10: 1.9474839e+08
A11: IV0010 | B11: SO0010 | C11: Reguler | D11: East Java | E11: NET90 | F11: 32352 | G11: 0.11 | H11: 7.4271669e+08
A12: IV0011 | B12: SO0011 | C12: Cargo | D12: Central Kalimantan | E12: COD | F12: 808800 | G12: 0.11 | H12: 78721154
A13: IV0012 | B13: SO0012 | C13: Cargo | D13: North Maluku | E13: COD | F13: 859350 | G13: 0.11 | H13: 109139739
... A1029: IV1028 | B1029: SO1028 | C1029: Reguler | D1029: East Java | E1029: NET90 | F1029: 32352 | G1029: 0.11 | H1029: 533399229
